<sdf version='1.11'>
  <model name='holybro'>
    <pose>0 0 0.23999999999999999 0 0 0</pose>
    <self_collide>false</self_collide>
    <static>false</static>
    <link name='base_link'>
      <inertial>
        <mass>2</mass>
        <inertia>
          <ixx>0.021666666666666671</ixx>
          <ixy>0</ixy>
          <ixz>0</ixz>
          <iyy>0.021666666666666671</iyy>
          <iyz>0</iyz>
          <izz>0.040000000000000008</izz>
        </inertia>
      </inertial>
      <gravity>true</gravity>
      <velocity_decay/>
      <visual name='base_link_visual'>
        <pose>0 0 0.025000000000000001 0 0 -3.1415926531795866</pose>
        <geometry>
          <mesh>
            <scale>1 1 1</scale>
            <uri>model://holybro_model/meshes/NXP-HGD-CF.dae</uri>
          </mesh>
        </geometry>
      </visual>
      <visual name='5010_motor_base_0'>
        <pose>0.17399999999999999 0.17399999999999999 0.032000000000000001 0 0 -0.45000000000000001</pose>
        <geometry>
          <mesh>
            <scale>1 1 1</scale>
            <uri>model://holybro_model/meshes/5010Base.dae</uri>
          </mesh>
        </geometry>
      </visual>
      <visual name='5010_motor_base_1'>
        <pose>-0.17399999999999999 0.17399999999999999 0.032000000000000001 0 0 -0.45000000000000001</pose>
        <geometry>
          <mesh>
            <scale>1 1 1</scale>
            <uri>model://holybro_model/meshes/5010Base.dae</uri>
          </mesh>
        </geometry>
      </visual>
      <visual name='5010_motor_base_2'>
        <pose>0.17399999999999999 -0.17399999999999999 0.032000000000000001 0 0 -0.45000000000000001</pose>
        <geometry>
          <mesh>
            <scale>1 1 1</scale>
            <uri>model://holybro_model/meshes/5010Base.dae</uri>
          </mesh>
        </geometry>
      </visual>
      <visual name='5010_motor_base_3'>
        <pose>-0.17399999999999999 -0.17399999999999999 0.032000000000000001 0 0 -0.45000000000000001</pose>
        <geometry>
          <mesh>
            <scale>1 1 1</scale>
            <uri>model://holybro_model/meshes/5010Base.dae</uri>
          </mesh>
        </geometry>
      </visual>
      <visual name='NXP_FMUK66_FRONT'>
        <pose>0.047 0.001 0.042999999999999997 1 1.0200012101279379e-16 1.5699999999999998</pose>
        <cast_shadows>false</cast_shadows>
        <geometry>
          <plane>
            <normal>0 0 1</normal>
            <size>0.012999999999999999 0.0070000000000000001</size>
          </plane>
        </geometry>
        <material>
          <diffuse>1 1 1 1</diffuse>
          <specular>1 1 1 1</specular>
          <pbr>
            <metal>
              <albedo_map>model://holybro_model/materials/textures/nxp.png</albedo_map>
            </metal>
          </pbr>
        </material>
      </visual>
      <visual name='NXP_FMUK66_TOP'>
        <pose>-0.023 0 0.051499999999999997 0 0 -1.5700000000000001</pose>
        <cast_shadows>false</cast_shadows>
        <geometry>
          <plane>
            <normal>0 0 1</normal>
            <size>0.012999999999999999 0.0070000000000000001</size>
          </plane>
        </geometry>
        <material>
          <diffuse>1 1 1 1</diffuse>
          <specular>1 1 1 1</specular>
          <pbr>
            <metal>
              <albedo_map>model://holybro_model/materials/textures/nxp.png</albedo_map>
            </metal>
          </pbr>
        </material>
      </visual>
      <visual name='RDDRONE_FMUK66_TOP'>
        <pose>-0.029999999999999999 0 0.051499999999999997 0 0 -1.5700000000000001</pose>
        <cast_shadows>false</cast_shadows>
        <geometry>
          <plane>
            <normal>0 0 1</normal>
            <size>0.032000000000000001 0.0033999999999999998</size>
          </plane>
        </geometry>
        <material>
          <diffuse>1 1 1 1</diffuse>
          <specular>1 1 1 1</specular>
          <pbr>
            <metal>
              <albedo_map>model://holybro_model/materials/textures/rd.png</albedo_map>
            </metal>
          </pbr>
        </material>
      </visual>
      <collision name='base_link_collision_0'>
        <pose>0 0 0.0070000000000000001 0 0 0</pose>
        <geometry>
          <box>
            <size>0.35355339059327373 0.35355339059327373 0.050000000000000003</size>
          </box>
        </geometry>
        <surface>
          <contact>
            <ode>
              <min_depth>0.001</min_depth>
              <max_vel>0</max_vel>
            </ode>
          </contact>
          <friction>
            <ode/>
          </friction>
        </surface>
      </collision>
      <collision name='base_link_collision_1'>
        <pose>0 -0.098000000000000004 -0.123 -0.34999999999999998 0 0</pose>
        <geometry>
          <box>
            <size>0.014999999999999999 0.014999999999999999 0.20999999999999999</size>
          </box>
        </geometry>
        <surface>
          <contact>
            <ode>
              <min_depth>0.001</min_depth>
              <max_vel>0</max_vel>
            </ode>
          </contact>
          <friction>
            <ode/>
          </friction>
        </surface>
      </collision>
      <collision name='base_link_collision_2'>
        <pose>0 0.098000000000000004 -0.123 0.34999999999999998 0 0</pose>
        <geometry>
          <box>
            <size>0.014999999999999999 0.014999999999999999 0.20999999999999999</size>
          </box>
        </geometry>
        <surface>
          <contact>
            <ode>
              <min_depth>0.001</min_depth>
              <max_vel>0</max_vel>
            </ode>
          </contact>
          <friction>
            <ode/>
          </friction>
        </surface>
      </collision>
      <collision name='base_link_collision_3'>
        <pose>0 -0.13200000000000001 -0.2195 0 0 0</pose>
        <geometry>
          <box>
            <size>0.25 0.014999999999999999 0.014999999999999999</size>
          </box>
        </geometry>
        <surface>
          <contact>
            <ode>
              <min_depth>0.001</min_depth>
              <max_vel>0</max_vel>
            </ode>
          </contact>
          <friction>
            <ode/>
          </friction>
        </surface>
      </collision>
      <collision name='base_link_collision_4'>
        <pose>0 0.13200000000000001 -0.2195 0 0 0</pose>
        <geometry>
          <box>
            <size>0.25 0.014999999999999999 0.014999999999999999</size>
          </box>
        </geometry>
        <surface>
          <contact>
            <ode>
              <min_depth>0.001</min_depth>
              <max_vel>0</max_vel>
            </ode>
          </contact>
          <friction>
            <ode/>
          </friction>
        </surface>
      </collision>
      <sensor name='air_pressure_sensor' type='air_pressure'>
        <always_on>true</always_on>
        <update_rate>50</update_rate>
        <air_pressure>
          <pressure>
            <noise type='gaussian'>
              <mean>0</mean>
              <stddev>0.01</stddev>
            </noise>
          </pressure>
        </air_pressure>
      </sensor>
      <sensor name='imu_sensor' type='imu'>
        <always_on>true</always_on>
        <update_rate>250</update_rate>
        <imu>
          <angular_velocity>
            <x>
              <noise type='gaussian'>
                <mean>0</mean>
                <stddev>0.00018665000000000001</stddev>
                <dynamic_bias_stddev>3.8785000000000002e-05</dynamic_bias_stddev>
                <dynamic_bias_correlation_time>1000</dynamic_bias_correlation_time>
              </noise>
            </x>
            <y>
              <noise type='gaussian'>
                <mean>0</mean>
                <stddev>0.00018665000000000001</stddev>
                <dynamic_bias_stddev>3.8785000000000002e-05</dynamic_bias_stddev>
                <dynamic_bias_correlation_time>1000</dynamic_bias_correlation_time>
              </noise>
            </y>
            <z>
              <noise type='gaussian'>
                <mean>0</mean>
                <stddev>0.00018665000000000001</stddev>
                <dynamic_bias_stddev>3.8785000000000002e-05</dynamic_bias_stddev>
                <dynamic_bias_correlation_time>1000</dynamic_bias_correlation_time>
              </noise>
            </z>
          </angular_velocity>
          <linear_acceleration>
            <x>
              <noise type='gaussian'>
                <mean>0</mean>
                <stddev>0.0018600000000000001</stddev>
                <dynamic_bias_stddev>0.0060000000000000001</dynamic_bias_stddev>
                <dynamic_bias_correlation_time>300</dynamic_bias_correlation_time>
              </noise>
            </x>
            <y>
              <noise type='gaussian'>
                <mean>0</mean>
                <stddev>0.0018600000000000001</stddev>
                <dynamic_bias_stddev>0.0060000000000000001</dynamic_bias_stddev>
                <dynamic_bias_correlation_time>300</dynamic_bias_correlation_time>
              </noise>
            </y>
            <z>
              <noise type='gaussian'>
                <mean>0</mean>
                <stddev>0.0018600000000000001</stddev>
                <dynamic_bias_stddev>0.0060000000000000001</dynamic_bias_stddev>
                <dynamic_bias_correlation_time>300</dynamic_bias_correlation_time>
              </noise>
            </z>
          </linear_acceleration>
        </imu>
      </sensor>
      <sensor name='navsat_sensor' type='navsat'>
        <always_on>true</always_on>
        <update_rate>30</update_rate>
      </sensor>
    </link>
    <link name='rotor_0'>
      <gravity>true</gravity>
      <self_collide>false</self_collide>
      <velocity_decay/>
      <pose>0.17399999999999999 -0.17399999999999999 0.059999999999999998 0 0 0</pose>
      <inertial>
        <mass>0.016076923076923075</mass>
        <inertia>
          <ixx>3.8464910483993325e-07</ixx>
          <iyy>2.6115851691700804e-05</iyy>
          <izz>2.6498582347140039e-05</izz>
          <ixy>0</ixy>
          <ixz>0</ixz>
          <iyz>0</iyz>
        </inertia>
      </inertial>
      <visual name='rotor_0_visual'>
        <pose>-0.021999999999999999 -0.14638461538461536 -0.016 0 0 0</pose>
        <geometry>
          <mesh>
            <scale>0.84615384615384615 0.84615384615384615 0.84615384615384615</scale>
            <uri>model://holybro_model/meshes/1345_prop_ccw.stl</uri>
          </mesh>
        </geometry>
        <material>
          <script>
            <name>Gazebo/DarkGrey</name>
            <uri>file://media/materials/scripts/gazebo.material</uri>
          </script>
        </material>
      </visual>
      <visual name='rotor_0_visual_motor_bell'>
        <pose>0 0 -0.032000000000000001 0 0 0</pose>
        <geometry>
          <mesh>
            <scale>1 1 1</scale>
            <uri>model://holybro_model/meshes/5010Bell.dae</uri>
          </mesh>
        </geometry>
      </visual>
      <collision name='rotor_0_collision'>
        <pose>0 0 0 0 0 0</pose>
        <geometry>
          <box>
            <size>0.27923076923076923 0.016923076923076923 0.0008461538461538462</size>
          </box>
        </geometry>
        <surface>
          <contact>
            <ode>
              <min_depth>0.001</min_depth>
              <max_vel>0</max_vel>
            </ode>
          </contact>
          <friction>
            <ode/>
          </friction>
        </surface>
      </collision>
    </link>
    <joint name='rotor_0_joint' type='revolute'>
      <parent>base_link</parent>
      <child>rotor_0</child>
      <axis>
        <xyz>0 0 1</xyz>
        <limit>
          <lower>-10000000000000000</lower>
          <upper>10000000000000000</upper>
        </limit>
        <dynamics>
          <spring_reference>0</spring_reference>
          <spring_stiffness>0</spring_stiffness>
        </dynamics>
      </axis>
    </joint>
    <link name='rotor_1'>
      <gravity>true</gravity>
      <self_collide>false</self_collide>
      <velocity_decay/>
      <pose>-0.17399999999999999 0.17399999999999999 0.059999999999999998 0 0 0</pose>
      <inertial>
        <mass>0.016076923076923075</mass>
        <inertia>
          <ixx>3.8464910483993325e-07</ixx>
          <iyy>2.6115851691700804e-05</iyy>
          <izz>2.6498582347140039e-05</izz>
          <ixy>0</ixy>
          <ixz>0</ixz>
          <iyz>0</iyz>
        </inertia>
      </inertial>
      <visual name='rotor_1_visual'>
        <pose>-0.021999999999999999 -0.14638461538461536 -0.016 0 0 0</pose>
        <geometry>
          <mesh>
            <scale>0.84615384615384615 0.84615384615384615 0.84615384615384615</scale>
            <uri>model://holybro_model/meshes/1345_prop_ccw.stl</uri>
          </mesh>
        </geometry>
        <material>
          <script>
            <name>Gazebo/DarkGrey</name>
            <uri>file://media/materials/scripts/gazebo.material</uri>
          </script>
        </material>
      </visual>
      <visual name='rotor_1_visual_motor_top'>
        <pose>0 0 -0.032000000000000001 0 0 0</pose>
        <geometry>
          <mesh>
            <scale>1 1 1</scale>
            <uri>model://holybro_model/meshes/5010Bell.dae</uri>
          </mesh>
        </geometry>
      </visual>
      <collision name='rotor_1_collision'>
        <pose>0 0 0 0 0 0</pose>
        <geometry>
          <box>
            <size>0.27923076923076923 0.016923076923076923 0.0008461538461538462</size>
          </box>
        </geometry>
        <surface>
          <contact>
            <ode>
              <min_depth>0.001</min_depth>
              <max_vel>0</max_vel>
            </ode>
          </contact>
          <friction>
            <ode/>
          </friction>
        </surface>
      </collision>
    </link>
    <joint name='rotor_1_joint' type='revolute'>
      <parent>base_link</parent>
      <child>rotor_1</child>
      <axis>
        <xyz>0 0 1</xyz>
        <limit>
          <lower>-10000000000000000</lower>
          <upper>10000000000000000</upper>
        </limit>
        <dynamics>
          <spring_reference>0</spring_reference>
          <spring_stiffness>0</spring_stiffness>
        </dynamics>
      </axis>
    </joint>
    <link name='rotor_2'>
      <gravity>true</gravity>
      <self_collide>false</self_collide>
      <velocity_decay/>
      <pose>0.17399999999999999 0.17399999999999999 0.059999999999999998 0 0 0</pose>
      <inertial>
        <mass>0.016076923076923075</mass>
        <inertia>
          <ixx>3.8464910483993325e-07</ixx>
          <iyy>2.6115851691700804e-05</iyy>
          <izz>2.6498582347140039e-05</izz>
          <ixy>0</ixy>
          <ixz>0</ixz>
          <iyz>0</iyz>
        </inertia>
      </inertial>
      <visual name='rotor_2_visual'>
        <pose>-0.021999999999999999 -0.14638461538461536 -0.016 0 0 0</pose>
        <geometry>
          <mesh>
            <scale>0.84615384615384615 0.84615384615384615 0.84615384615384615</scale>
            <uri>model://holybro_model/meshes/1345_prop_cw.stl</uri>
          </mesh>
        </geometry>
        <material>
          <script>
            <name>Gazebo/DarkGrey</name>
            <uri>file://media/materials/scripts/gazebo.material</uri>
          </script>
        </material>
      </visual>
      <visual name='rotor_2_visual_motor_top'>
        <pose>0 0 -0.032000000000000001 0 0 0</pose>
        <geometry>
          <mesh>
            <scale>1 1 1</scale>
            <uri>model://holybro_model/meshes/5010Bell.dae</uri>
          </mesh>
        </geometry>
      </visual>
      <collision name='rotor_2_collision'>
        <pose>0 0 0 0 0 0</pose>
        <geometry>
          <box>
            <size>0.27923076923076923 0.016923076923076923 0.0008461538461538462</size>
          </box>
        </geometry>
        <surface>
          <contact>
            <ode>
              <min_depth>0.001</min_depth>
              <max_vel>0</max_vel>
            </ode>
          </contact>
          <friction>
            <ode/>
          </friction>
        </surface>
      </collision>
    </link>
    <joint name='rotor_2_joint' type='revolute'>
      <parent>base_link</parent>
      <child>rotor_2</child>
      <axis>
        <xyz>0 0 1</xyz>
        <limit>
          <lower>-10000000000000000</lower>
          <upper>10000000000000000</upper>
        </limit>
        <dynamics>
          <spring_reference>0</spring_reference>
          <spring_stiffness>0</spring_stiffness>
        </dynamics>
      </axis>
    </joint>
    <link name='rotor_3'>
      <gravity>true</gravity>
      <self_collide>false</self_collide>
      <velocity_decay/>
      <pose>-0.17399999999999999 -0.17399999999999999 0.059999999999999998 0 0 0</pose>
      <inertial>
        <mass>0.016076923076923075</mass>
        <inertia>
          <ixx>3.8464910483993325e-07</ixx>
          <iyy>2.6115851691700804e-05</iyy>
          <izz>2.6498582347140039e-05</izz>
          <ixy>0</ixy>
          <ixz>0</ixz>
          <iyz>0</iyz>
        </inertia>
      </inertial>
      <visual name='rotor_3_visual'>
        <pose>-0.021999999999999999 -0.14638461538461536 -0.016 0 0 0</pose>
        <geometry>
          <mesh>
            <scale>0.84615384615384615 0.84615384615384615 0.84615384615384615</scale>
            <uri>model://holybro_model/meshes/1345_prop_cw.stl</uri>
          </mesh>
        </geometry>
        <material>
          <script>
            <name>Gazebo/DarkGrey</name>
            <uri>file://media/materials/scripts/gazebo.material</uri>
          </script>
        </material>
      </visual>
      <visual name='rotor_3_visual_motor_top'>
        <pose>0 0 -0.032000000000000001 0 0 0</pose>
        <geometry>
          <mesh>
            <scale>1 1 1</scale>
            <uri>model://holybro_model/meshes/5010Bell.dae</uri>
          </mesh>
        </geometry>
      </visual>
      <collision name='rotor_3_collision'>
        <pose>0 0 0 0 0 0</pose>
        <geometry>
          <box>
            <size>0.27923076923076923 0.016923076923076923 0.0008461538461538462</size>
          </box>
        </geometry>
        <surface>
          <contact>
            <ode>
              <min_depth>0.001</min_depth>
              <max_vel>0</max_vel>
            </ode>
          </contact>
          <friction>
            <ode/>
          </friction>
        </surface>
      </collision>
    </link>
    <joint name='rotor_3_joint' type='revolute'>
      <parent>base_link</parent>
      <child>rotor_3</child>
      <axis>
        <xyz>0 0 1</xyz>
        <limit>
          <lower>-10000000000000000</lower>
          <upper>10000000000000000</upper>
        </limit>
        <dynamics>
          <spring_reference>0</spring_reference>
          <spring_stiffness>0</spring_stiffness>
        </dynamics>
      </axis>
    </joint>
  </model>
</sdf>
