<?xml version="1.0"?>
<robot name="holybro">

  <!-- Base Link -->
  <link name="base_link">
    <visual>
      <geometry>
        <mesh filename="package://holybro_model/meshes/NXP-HGD-CF.dae" scale="1 1 1"/>
      </geometry>
    </visual>
  </link>

  <!-- Base Links -->
  <link name="base_0_link">
    <visual>
      <geometry>
        <mesh filename="package://holybro_model/meshes/5010Base.dae" scale="0.846 0.846 0.846"/>
      </geometry>
    </visual>
  </link>
  
  <link name="base_1_link">
    <visual>
      <geometry>
        <mesh filename="package://holybro_model/meshes/5010Base.dae" scale="0.846 0.846 0.846"/>
      </geometry>
    </visual>
  </link>

  <link name="base_2_link">
    <visual>
      <geometry>
        <mesh filename="package://holybro_model/meshes/5010Base.dae" scale="0.846 0.846 0.846"/>
      </geometry>
    </visual>
  </link>
  
  <link name="base_3_link">
    <visual>
      <geometry>
        <mesh filename="package://holybro_model/meshes/5010Base.dae" scale="0.846 0.846 0.846"/>
      </geometry>
    </visual>
  </link>
  
  <!-- Bell Links -->
  <link name="bell_0_link">
    <visual>
      <geometry>
        <mesh filename="package://holybro_model/meshes/5010Bell.dae" scale="0.846 0.846 0.846"/>
      </geometry>
    </visual>
  </link>
  
  <link name="bell_1_link">
    <visual>
      <geometry>
        <mesh filename="package://holybro_model/meshes/5010Bell.dae" scale="0.846 0.846 0.846"/>
      </geometry>
    </visual>
  </link>

  <link name="bell_2_link">
    <visual>
      <geometry>
        <mesh filename="package://holybro_model/meshes/5010Bell.dae" scale="0.846 0.846 0.846"/>
      </geometry>
    </visual>
  </link>
  
  <link name="bell_3_link">
    <visual>
      <geometry>
        <mesh filename="package://holybro_model/meshes/5010Bell.dae" scale="0.846 0.846 0.846"/>
      </geometry>
    </visual>
  </link>
  
  <!-- Rotor Links -->
  <link name="rotor_0_link">
    <visual>
      <geometry>
        <mesh filename="package://holybro_model/meshes/1345_prop_ccw_center.stl" scale="0.846 0.846 0.846"/>
      </geometry>
    </visual>
  </link>
  
  <link name="rotor_1_link">
    <visual>
      <geometry>
        <mesh filename="package://holybro_model/meshes/1345_prop_ccw_center.stl" scale="0.846 0.846 0.846"/>
      </geometry>
    </visual>
  </link>

  <link name="rotor_2_link">
    <visual>
      <geometry>
        <mesh filename="package://holybro_model/meshes/1345_prop_ccw_center.stl" scale="0.846 0.846 0.846"/>
      </geometry>
    </visual>
  </link>
  
  <link name="rotor_3_link">
    <visual>
      <geometry>
        <mesh filename="package://holybro_model/meshes/1345_prop_ccw_center.stl" scale="0.846 0.846 0.846"/>
      </geometry>
    </visual>
  </link>
  
  <!-- IMU Link -->
  <link name="imu_link"/>

  <!-- GPS Base Link -->
  <link name="gps_base_link">
    <visual>
      <origin xyz="0.0 0.0 0.05" rpy="0 0 0"/>
      <geometry>
        <cylinder length="0.1" radius="0.005"/>
      </geometry>
      <material name="grey">
        <color rgba="0.5 0.5 0.5 1"/>
      </material>
    </visual>
  </link>
  
  <!-- GPS Link -->
  <link name="gps_link">
    <visual>
      <geometry>
        <cylinder length="0.01" radius="0.02"/>
      </geometry>
      <material name="grey">
        <color rgba="0.5 0.5 0.5 1"/>
      </material>
    </visual>
  </link>
  
  <!-- Lidar Links -->
  <link name="lidar_link">
    <visual>
      <geometry>
        <box size="0.05 0.08 0.03" />
      </geometry>
      <material name="gray">
        <color rgba="0.5 0.5 0.5 1.0"/>
      </material>
    </visual>
  </link>

  <link name="lidar_base_link"/>
  <link name="livox_frame"/>
  
  <!-- Left Lens Visual (small square on the left) -->
  <link name="lidar_left_lens_link">
    <visual>
      <geometry>
        <box size="0.025 0.025 0.03" /> <!-- Small square 1.5x1.5cm -->
      </geometry>
      <material name="black">
        <color rgba="0 0 0 1.0"/>
      </material>
    </visual>
  </link>

  <!-- Right Lens Visual (small square on the right) -->
  <link name="lidar_right_lens_link">
    <visual>
      <geometry>
        <box size="0.025 0.025 0.03" /> <!-- Small square 1.5x1.5cm -->
      </geometry>
      <material name="black">
        <color rgba="0 0 0 1.0"/>
      </material>
    </visual>
  </link>
  
  <!-- Base Joints -->
  <joint name="base_0_joint" type="fixed">
    <parent link="base_link"/>
    <child link="base_0_link"/>
    <origin xyz="0.174 -0.174 0.00" rpy="0 0 0"/>
  </joint>

  <joint name="base_1_joint" type="fixed">
    <parent link="base_link"/>
    <child link="base_1_link"/>
    <origin xyz="-0.174 0.174 0.00" rpy="0 0 0"/>
  </joint>

  <joint name="base_2_joint" type="fixed">
    <parent link="base_link"/>
    <child link="base_2_link"/>
    <origin xyz="0.174 0.174 0.00" rpy="0 0 0"/>
  </joint>

  <joint name="base_3_joint" type="fixed">
    <parent link="base_link"/>
    <child link="base_3_link"/>
    <origin xyz="-0.174 -0.174 0.00" rpy="0 0 0"/>
    <axis xyz="0 0 1"/>
  </joint>
  
  <!-- Bell Joints -->
  <joint name="bell_0_joint" type="fixed">
    <parent link="base_0_link"/>
    <child link="bell_0_link"/>
    <origin xyz="0.00 0.00 0.00" rpy="0 0 0"/>
  </joint>

  <joint name="bell_1_joint" type="fixed">
    <parent link="base_1_link"/>
    <child link="bell_1_link"/>
    <origin xyz="0.00 0.00 0.00" rpy="0 0 0"/>
  </joint>

  <joint name="bell_2_joint" type="fixed">
    <parent link="base_2_link"/>
    <child link="bell_2_link"/>
    <origin xyz="0.00 0.00 0.00" rpy="0 0 0"/>
  </joint>

  <joint name="bell_3_joint" type="fixed">
    <parent link="base_3_link"/>
    <child link="bell_3_link"/>
    <origin xyz="0.00 0.00 0.00" rpy="0 0 0"/>
  </joint>
  
  <!-- Rotor Joints -->
  <joint name="rotor_0_joint" type="continuous">
    <parent link="bell_0_link"/>
    <child link="rotor_0_link"/>
    <origin xyz="0.00 0.00 0.018" rpy="0 0 0"/>
    <axis xyz="0 0 1"/>
  </joint>

  <joint name="rotor_1_joint" type="continuous">
    <parent link="bell_1_link"/>
    <child link="rotor_1_link"/>
    <origin xyz="0.00 0.00 0.018" rpy="0 0 0"/>
    <axis xyz="0 0 1"/>
  </joint>

  <joint name="rotor_2_joint" type="continuous">
    <parent link="bell_2_link"/>
    <child link="rotor_2_link"/>
    <origin xyz="0.00 0.00 0.018" rpy="0 0 0"/>
    <axis xyz="0 0 1"/>
  </joint>

  <joint name="rotor_3_joint" type="continuous">
    <parent link="bell_3_link"/>
    <child link="rotor_3_link"/>
    <origin xyz="0.00 0.00 0.018" rpy="0 0 0"/>
    <axis xyz="0 0 1"/>
  </joint>

  <!-- Imu Joints -->
  <joint name="imu_joint" type="fixed">
    <parent link="base_link"/>
    <child link="imu_link"/>
    <origin xyz="0.00 0.00 0.02" rpy="0 0 0"/>
  </joint>
  
  <!-- GPS Base Joints -->
  <joint name="gps_base_joint" type="fixed">
    <parent link="base_link"/>
    <child link="gps_base_link"/>
    <origin xyz="-0.03 -0.05 0.00" rpy="0 0 0"/>
  </joint>
  
  <!-- GPS  Joints -->
  <joint name="gps_joint" type="fixed">
    <parent link="gps_base_link"/>
    <child link="gps_link"/>
    <origin xyz="0.00 0.00 0.1" rpy="0 0 0"/>
  </joint>
  
  <!-- Lidar Joints -->
  <!-- Joint for the left lens -->
  <joint name="lidar_left_lens_joint" type="fixed">
    <parent link="lidar_link"/>
    <child link="lidar_left_lens_link"/>
    <origin xyz="0 0.02 0.0005" rpy="0 0 0"/> <!-- Left position at -0.75 relative to the width -->
  </joint>

  <!-- Joint for the right lens -->
  <joint name="lidar_right_lens_joint" type="fixed">
    <parent link="lidar_link"/>
    <child link="lidar_right_lens_link"/>
    <origin xyz="0 -0.02 0.0005" rpy="0 0 0"/> <!-- Right position at +0.75 relative to the width -->
  </joint>

  <!-- Joint for static transform between base and sensor -->
  <joint name="lidar_base_joint_trans" type="fixed">
    <parent link="base_link"/>
    <child link="lidar_base_link"/>
    <origin xyz="0.08 0.0 -0.06" rpy="0 0 0"/>
  </joint>

  <!-- Joint for static transform between base and sensor -->
  <joint name="lidar_base_joint_rot" type="fixed">
    <parent link="lidar_base_link"/>
    <child link="lidar_link"/>
    <origin xyz="0.0 0.0 0.0" rpy="0 0 0"/>
  </joint>

    <!-- Joint for static transform between base and sensor -->
  <joint name="livox_frame_joint" type="fixed">
    <parent link="lidar_link"/>
    <child link="livox_frame"/>
    <origin xyz="0.0 0.0 0.0" rpy="0.0 0.0 3.1415926"/>
  </joint>
  
</robot>

